Workbook

Sheet Listas
A1: ID | B1: Corregimiento | C1: Veredas | D1: Area_km2
A2: 1 | B2: Atuncela | C2: Puerto Dagua | D2: 292,13
A3: 2 | B3: Borrero Ayerbe | C3: Km 26, Ambichinte, Pueblo Nuevo, El Vergel, Km 28, Agua Sucia, El Crucero, La Zulia y El Descanso | D3: 204,95
A4: 3 | B4: Cisneros | C4: La Guinea Baja y La Guinea Alta | D4: 79,65
A5: 4 | B5: El Carmen | C5: La Clorinda, Las Tórtolas, Loma Linda, El Galpón y Bahondo | D5: 367,07
A6: 5 | B6: El Danubio | C6: Km 81 y Los Monos | D6: 481,96
A7: 6 | B7: El Limonar | C7: El Chilcal, Monterredondo, Honduras, El Tablazo, Consuegra, La Soledad y Junticas | D7: 322,32
A8: 7 | B8: El Naranjo | C8: La Reina, Peñas Gordas, La Victoria y Galeras | D8: 112,25
A9: 8 | B9: El Palmar | C9: Las Brisas, La Colonia, Centella, Puerto Cosson, Yerbabuena, La Virgen, La Pulida y Palo Alto | D9: 274,05
A10: 9 | B10: El Pinal | C10: Bolivia, Manantiales y El Zapote | D10: 408,85
A11: 10 | B11: El Queremal | C11: Las Camellas, La Rosita, Machado, El Almorzadero, El Tigre, Sendo, Potrerillo y Paraguitas | D11: 979,1
A12: 11 | B12: El Rucio | C12: La Samaria, Vista Hermosa y La Floresta | D12: 276,9
A13: 12 | B13: El Salado | C13: Piedra Pintada, San Antonio, El Aguacate y El Porvenir | D13: 195
A14: 13 | B14: Jiguales | D14: 135,52
A15: 14 | B15: Juntas | C15: La Puerta, San Cristóbal, La Cedrera, La Siria y Sombrerillos | D15: 416,5
A16: 15 | B16: Kilómetro 18 | D16: 60,75
A17: 16 | B17: La Cascada | C17: El Placer, La Mona y El Cauchal | D17: 298,21
A18: 17 | B18: La Elsa | C18: El Engano, Río Blanco, El Digua y Las Curvas | D18: 1.244,6
A19: 18 | B19: Loboguerrero | C19: La Yolomba y La Chapa | D19: 286,8
A20: 19 | B20: Los Alpes | C20: La Garza, Amapola, El Rosal y La Virgen | D20: 234,7
A21: 20 | B21: Los Cristales | C21: Tolda Seca, Vega Grande, Pepitas y El Hormiguero | D21: 538,4
A22: 21 | B22: Providencia | C22: La Esmeralda | D22: 803,7
A23: 22 | B23: San Bernardo | C23: El Jordán, El Jordancito, San Miguel, El Triunfo, El Diviso, Loma Alta, La Tigra, Ben Hur, San Luis y Tocotá | D23: 338,27
A24: 23 | B24: San Vicente | C24: El Pajal y San Joaquín | D24: 457,72
A25: 24 | B25: Santa María | C25: Siempreviva, Cerro Azul y Anegas | D25: 320,41
A26: 25 | B26: Villahermosa | C26: La Esperanza, Las Camelias- K. 95 y Las Delicias | D26: 126,57
A27: 26 | B27: Zabaletas | C27: Carrisales, Bella Vista, El Trapiche y La Velmira | D27: 188,79
A28: 27 | B28: Zelandia | C28: Aguas Lindas | D28: 430

Sheet ABC COSTEO
A1: COSTEO ABC – ACTIVITY BASED COSTING · TRIPLE AAA
A2: Metodología: Kaplan & Cooper (1998) adaptada a transporte PYME colombiano (Mora García, 2008)
A4: DRIVER 1 – COSTOS POR ACTIVIDAD DE VIAJE
A5: Rubro | B5: Monto Mensual | C5: Clasificación | D5: Justificación
A6: Conductor – salario+prest. (2) | B6: 5124456 | C6: Costo Fijo | D6: Personal debe pagarse cada mes
A7: Ayudante – salario+prest. (2) | B7: 4594580 | C7: Costo Fijo | D7: Personal debe pagarse cada mes
A8: Bocato | B8: 58666.67 | C8: Costo Fijo | D8: Minicargador
A9: TOTAL COSTOS FIJOS (Driver 1) | B9: =SUM(B6:B8) -> 9777702.7 | C9: 67.13% del total
A10: ÷ Viajes estimados al mes | B10: =COUNT(Tabla3[N° FACTURA]) -> 240 | D10: Envios en el mes de noviembre
A11: CF POR VIAJE (costo fijo de salir una vez) | B11: =IFERROR(B9/B10,0) -> 40740.428
A13: DRIVER 2 – COSTOS POR KM RECORRIDO (variables con la distancia)
A14: Rubro | B14: Monto Mensual | C14: Clasificación | D14: Justificación
A15: ACPM / Diesel (2 vehículos) | B15: 1893969 | C15: Costo Variable | D15: A mayor km, mayor consumo
A16: Mantenimiento (2 vehículos) | B16: 1000000 | C16: Semi-Variable | D16: Se intensifica con el uso del vehículo
A17: TOTAL COSTOS VARIABLES (Driver 2) | B17: =SUM(B15:B16) -> 2893969 | C17: 32.87% del total | D17: 21% son costos VARIABLES — crecen con los km recorridos
A18: × Km promedio por viaje (solo ida) | B18: =AVERAGE(Tabla3[DISTANCIA (km)]) -> 4.4318197 | D18: Promedio calculado de la base de noviembre
A19: × Factor 2 (vehículo regresa vacío desde destino) | B19: 2
A20: Km totales recorridos al mes | B20: =B10*B18*2 -> 2127.2734
A21: CV POR KM (costo variable por cada km adicional) | B21: =IFERROR(B17/B20,0) -> 1360.4123 | D21: Por cada km extra de distancia, este es el costo adicional
A23: RESUMEN ABC – FÓRMULA DE COSTO POR ENVÍO
A24: Ingrese la distancia del envío (km ida) | B24: 5.5 | D24: ← Ejemplo: Limonar 5.5 km
A25: Peso estimado del envío (kg) | B25: 45 | D25: ← Ferretería: promedio estimado 45 kg
A26: Factor peso (recargo si >50 kg) | B26: =IF(B25>50,1+(B25-50)*0.002,1) -> 1 | D26: Mora García (2008): recargo proporcional al exceso de peso
A27: Número de viajes / transportes | B27: 1
A28: Componente 1 – Costo fijo del viaje | B28: =IFERROR(B9/B10*B27,0) -> 40740.428 | D28: CF/viaje × número de transportes
A29: Componente 2 – Costo variable por km | B29: =B24*2*IFERROR(4787938/B20,0)*B26*B27 -> 24758.133 | D29: CV/km × distancia×2 × factor peso × transportes
A30: COSTO ABC TOTAL DEL ENVÍO | B30: =B28+B29 -> 65498.56 | D30: Kaplan & Cooper: suma de todos los drivers de costo

Sheet Fechas Y ubicaciones
A1: Fecha | B1: Total de envios | C1: Valor | E1: Nombre | F1: Numero de Facturas | G1: Numero de envios | H1: % | I1: Valor envio | J1: Promedio | K1: Distancia (KM) | L1: Distancia total ida y vuelta | N1: Corregimiento | O1: Total de transportes | P1: Valor total de transporte | Q1: Distancia Promedio por corregimiento | R1: Valor promedio de transporte por corregimiento | S1: Valor promedio del costo calculo con ABC | T1: Perdida promedio de margen
A2: 45962 | B2: =COUNTIF(Tabla3[FECHA],Tabla4[[#This Row],[Fecha]]) -> 14 | C2: =SUMIF(Tabla3[FECHA],Tabla4[[#This Row],[Fecha]],Tabla3[VLR. TRANSPORTE]) -> 695000 | E2: Parcelación Pirineos | F2: =COUNTIF(Tabla3[LUGAR ENVÍO],Tabla6[[#This Row],[Nombre]]) -> 0 | G2: =SUMIF(Tabla3[LUGAR ENVÍO],Tabla6[[#This Row],[Nombre]],Tabla3[Numero de Transportes]) -> 0 | H2: =Tabla6[[#This Row],[Numero de Facturas]]/Tabla6[[#Totals],[Numero de Facturas]] -> 0 | I2: =SUMIF(Tabla3[LUGAR ENVÍO],Tabla6[[#This Row],[Nombre]],Tabla3[VLR. TRANSPORTE]) -> 0 | J2: =AVERAGEIF(Tabla3[LUGAR ENVÍO],Tabla6[[#This Row],[Nombre]],Tabla3[VLR. TRANSPORTE]) -> #DIV/0! | K2: =Tabla6[[#This Row],[Distancia total ida y vuelta]]/Tabla6[[#This Row],[Numero de Facturas]] -> #DIV/0! | L2: =SUMIF(Tabla3[LUGAR ENVÍO],Tabla6[[#This Row],[Nombre]],Tabla3[DISTANCIA (km)]) -> 0 | N2: El Carmen | O2: =COUNTIF(Tabla3[Corregimiento],Tabla7[[#This Row],[Corregimiento]]) -> 101 | P2: =SUMIF(Tabla3[Corregimiento],Tabla7[[#This Row],[Corregimiento]],Tabla3[VLR. TRANSPORTE]) -> 5630000 | Q2: =AVERAGEIF(Tabla3[Corregimiento],Tabla7[[#This Row],[Corregimiento]],Tabla3[DISTANCIA (km)]) -> 4.2490918 | R2: =AVERAGEIF(Tabla3[Corregimiento],Tabla7[[#This Row],[Corregimiento]],Tabla3[Valor Tran]) -> 50495.05 | S2: =AVERAGEIF(Tabla8[Corregimiento],Tabla7[[#This Row],[Corregimiento]],Tabla8[Costo Total]) -> 52121.823 | T2: =AVERAGEIF(Tabla8[Corregimiento],Tabla7[[#This Row],[Corregimiento]],Tabla8[Perdida o ganancia de margen]) -> -0.063998881
A3: 45963 | B3: =COUNTIF(Tabla3[FECHA],Tabla4[[#This Row],[Fecha]]) -> 1 | C3: =SUMIF(Tabla3[FECHA],Tabla4[[#This Row],[Fecha]],Tabla3[VLR. TRANSPORTE]) -> 60000 | E3: El Coscorron | F3: =COUNTIF(Tabla3[LUGAR ENVÍO],Tabla6[[#This Row],[Nombre]]) -> 11 | G3: =SUMIF(Tabla3[LUGAR ENVÍO],Tabla6[[#This Row],[Nombre]],Tabla3[Numero de Transportes]) -> 15 | H3: =Tabla6[[#This Row],[Numero de Facturas]]/Tabla6[[#Totals],[Numero de Facturas]] -> 0.15942029 | I3: =SUMIF(Tabla3[LUGAR ENVÍO],Tabla6[[#This Row],[Nombre]],Tabla3[VLR. TRANSPORTE]) -> 985000 | J3: =AVERAGEIF(Tabla3[LUGAR ENVÍO],Tabla6[[#This Row],[Nombre]],Tabla3[VLR. TRANSPORTE]) -> 89545.455 | K3: =Tabla6[[#This Row],[Distancia total ida y vuelta]]/Tabla6[[#This Row],[Numero de Facturas]] -> 2.65 | L3: =SUMIF(Tabla3[LUGAR ENVÍO],Tabla6[[#This Row],[Nombre]],Tabla3[DISTANCIA (km)]) -> 29.15 | N3: Borrero Ayerbe | O3: =COUNTIF(Tabla3[Corregimiento],Tabla7[[#This Row],[Corregimiento]]) -> 90 | P3: =SUMIF(Tabla3[Corregimiento],Tabla7[[#This Row],[Corregimiento]],Tabla3[VLR. TRANSPORTE]) -> 4195000 | Q3: =AVERAGEIF(Tabla3[Corregimiento],Tabla7[[#This Row],[Corregimiento]],Tabla3[DISTANCIA (km)]) -> 2.4517922 | R3: =AVERAGEIF(Tabla3[Corregimiento],Tabla7[[#This Row],[Corregimiento]],Tabla3[Valor Tran]) -> 37222.222 | S3: =AVERAGEIF(Tabla8[Corregimiento],Tabla7[[#This Row],[Corregimiento]],Tabla8[Costo Total]) -> 47463.142 | T3: =AVERAGEIF(Tabla8[Corregimiento],Tabla7[[#This Row],[Corregimiento]],Tabla8[Perdida o ganancia de margen]) -> -0.13028936
A4: 45964 | B4: =COUNTIF(Tabla3[FECHA],Tabla4[[#This Row],[Fecha]]) -> 2 | C4: =SUMIF(Tabla3[FECHA],Tabla4[[#This Row],[Fecha]],Tabla3[VLR. TRANSPORTE]) -> 120000 | E4: Tortolas | F4: =COUNTIF(Tabla3[LUGAR ENVÍO],Tabla6[[#This Row],[Nombre]]) -> 7 | G4: =SUMIF(Tabla3[LUGAR ENVÍO],Tabla6[[#This Row],[Nombre]],Tabla3[Numero de Transportes]) -> 8 | H4: =Tabla6[[#This Row],[Numero de Facturas]]/Tabla6[[#Totals],[Numero de Facturas]] -> 0.10144928 | I4: =SUMIF(Tabla3[LUGAR ENVÍO],Tabla6[[#This Row],[Nombre]],Tabla3[VLR. TRANSPORTE]) -> 580000 | J4: =AVERAGEIF(Tabla3[LUGAR ENVÍO],Tabla6[[#This Row],[Nombre]],Tabla3[VLR. TRANSPORTE]) -> 82857.143 | K4: =Tabla6[[#This Row],[Distancia total ida y vuelta]]/Tabla6[[#This Row],[Numero de Facturas]] -> 5.757 | L4: =SUMIF(Tabla3[LUGAR ENVÍO],Tabla6[[#This Row],[Nombre]],Tabla3[DISTANCIA (km)]) -> 40.299 | N4: El Limonar | O4: =COUNTIF(Tabla3[Corregimiento],Tabla7[[#This Row],[Corregimiento]]) -> 26 | P4: =SUMIF(Tabla3[Corregimiento],Tabla7[[#This Row],[Corregimiento]],Tabla3[VLR. TRANSPORTE]) -> 1745000 | Q4: =AVERAGEIF(Tabla3[Corregimiento],Tabla7[[#This Row],[Corregimiento]],Tabla3[DISTANCIA (km)]) -> 6.2415442 | R4: =AVERAGEIF(Tabla3[Corregimiento],Tabla7[[#This Row],[Corregimiento]],Tabla3[Valor Tran]) -> 51730.769 | S4: =AVERAGEIF(Tabla8[Corregimiento],Tabla7[[#This Row],[Corregimiento]],Tabla8[Costo Total]) -> 57793.765 | T4: =AVERAGEIF(Tabla8[Corregimiento],Tabla7[[#This Row],[Corregimiento]],Tabla8[Perdida o ganancia de margen]) -> -0.14504127
A5: 45965 | B5: =COUNTIF(Tabla3[FECHA],Tabla4[[#This Row],[Fecha]]) -> 4 | C5: =SUMIF(Tabla3[FECHA],Tabla4[[#This Row],[Fecha]],Tabla3[VLR. TRANSPORTE]) -> 190000 | E5: KM 34 | F5: =COUNTIF(Tabla3[LUGAR ENVÍO],Tabla6[[#This Row],[Nombre]]) -> 8 | G5: =SUMIF(Tabla3[LUGAR ENVÍO],Tabla6[[#This Row],[Nombre]],Tabla3[Numero de Transportes]) -> 10 | H5: =Tabla6[[#This Row],[Numero de Facturas]]/Tabla6[[#Totals],[Numero de Facturas]] -> 0.11594203 | I5: =SUMIF(Tabla3[LUGAR ENVÍO],Tabla6[[#This Row],[Nombre]],Tabla3[VLR. TRANSPORTE]) -> 390000 | J5: =AVERAGEIF(Tabla3[LUGAR ENVÍO],Tabla6[[#This Row],[Nombre]],Tabla3[VLR. TRANSPORTE]) -> 48750 | K5: =Tabla6[[#This Row],[Distancia total ida y vuelta]]/Tabla6[[#This Row],[Numero de Facturas]] -> 4.316 | L5: =SUMIF(Tabla3[LUGAR ENVÍO],Tabla6[[#This Row],[Nombre]],Tabla3[DISTANCIA (km)]) -> 34.528 | N5: El Salado | O5: =COUNTIF(Tabla3[Corregimiento],Tabla7[[#This Row],[Corregimiento]]) -> 8 | P5: =SUMIF(Tabla3[Corregimiento],Tabla7[[#This Row],[Corregimiento]],Tabla3[VLR. TRANSPORTE]) -> 560000 | Q5: =AVERAGEIF(Tabla3[Corregimiento],Tabla7[[#This Row],[Corregimiento]],Tabla3[DISTANCIA (km)]) -> 11.97575 | R5: =AVERAGEIF(Tabla3[Corregimiento],Tabla7[[#This Row],[Corregimiento]],Tabla3[Valor Tran]) -> 57500 | S5: =AVERAGEIF(Tabla8[Corregimiento],Tabla7[[#This Row],[Corregimiento]],Tabla8[Costo Total]) -> 73324.343 | T5: =AVERAGEIF(Tabla8[Corregimiento],Tabla7[[#This Row],[Corregimiento]],Tabla8[Perdida o ganancia de margen]) -> -0.18768168
A6: 45966 | B6: =COUNTIF(Tabla3[FECHA],Tabla4[[#This Row],[Fecha]]) -> 9 | C6: =SUMIF(Tabla3[FECHA],Tabla4[[#This Row],[Fecha]],Tabla3[VLR. TRANSPORTE]) -> 495000 | E6: Altos del Carmen | F6: =COUNTIF(Tabla3[LUGAR ENVÍO],Tabla6[[#This Row],[Nombre]]) -> 9 | G6: =SUMIF(Tabla3[LUGAR ENVÍO],Tabla6[[#This Row],[Nombre]],Tabla3[Numero de Transportes]) -> 9 | H6: =Tabla6[[#This Row],[Numero de Facturas]]/Tabla6[[#Totals],[Numero de Facturas]] -> 0.13043478 | I6: =SUMIF(Tabla3[LUGAR ENVÍO],Tabla6[[#This Row],[Nombre]],Tabla3[VLR. TRANSPORTE]) -> 460000 | J6: =AVERAGEIF(Tabla3[LUGAR ENVÍO],Tabla6[[#This Row],[Nombre]],Tabla3[VLR. TRANSPORTE]) -> 51111.111 | K6: =Tabla6[[#This Row],[Distancia total ida y vuelta]]/Tabla6[[#This Row],[Numero de Facturas]] -> 5.464 | L6: =SUMIF(Tabla3[LUGAR ENVÍO],Tabla6[[#This Row],[Nombre]],Tabla3[DISTANCIA (km)]) -> 49.176 | N6: San Bernardo | O6: =COUNTIF(Tabla3[Corregimiento],Tabla7[[#This Row],[Corregimiento]]) -> 7 | P6: =SUMIF(Tabla3[Corregimiento],Tabla7[[#This Row],[Corregimiento]],Tabla3[VLR. TRANSPORTE]) -> 365000 | Q6: =AVERAGEIF(Tabla3[Corregimiento],Tabla7[[#This Row],[Corregimiento]],Tabla3[DISTANCIA (km)]) -> 9.1617143 | R6: =AVERAGEIF(Tabla3[Corregimiento],Tabla7[[#This Row],[Corregimiento]],Tabla3[Valor Tran]) -> 47857.143 | S6: =AVERAGEIF(Tabla8[Corregimiento],Tabla7[[#This Row],[Corregimiento]],Tabla8[Costo Total]) -> 65667.846 | T6: =AVERAGEIF(Tabla8[Corregimiento],Tabla7[[#This Row],[Corregimiento]],Tabla8[Perdida o ganancia de margen]) -> -0.19185042
A7: 45967 | B7: =COUNTIF(Tabla3[FECHA],Tabla4[[#This Row],[Fecha]]) -> 10 | C7: =SUMIF(Tabla3[FECHA],Tabla4[[#This Row],[Fecha]],Tabla3[VLR. TRANSPORTE]) -> 480000 | E7: Parcelacion la Cristalina | F7: =COUNTIF(Tabla3[LUGAR ENVÍO],Tabla6[[#This Row],[Nombre]]) -> 5 | G7: =SUMIF(Tabla3[LUGAR ENVÍO],Tabla6[[#This Row],[Nombre]],Tabla3[Numero de Transportes]) -> 5 | H7: =Tabla6[[#This Row],[Numero de Facturas]]/Tabla6[[#Totals],[Numero de Facturas]] -> 0.072463768 | I7: =SUMIF(Tabla3[LUGAR ENVÍO],Tabla6[[#This Row],[Nombre]],Tabla3[VLR. TRANSPORTE]) -> 270000 | J7: =AVERAGEIF(Tabla3[LUGAR ENVÍO],Tabla6[[#This Row],[Nombre]],Tabla3[VLR. TRANSPORTE]) -> 54000 | K7: =Tabla6[[#This Row],[Distancia total ida y vuelta]]/Tabla6[[#This Row],[Numero de Facturas]] -> 2.71 | L7: =SUMIF(Tabla3[LUGAR ENVÍO],Tabla6[[#This Row],[Nombre]],Tabla3[DISTANCIA (km)]) -> 13.55 | N7: El Queremal | O7: =COUNTIF(Tabla3[Corregimiento],Tabla7[[#This Row],[Corregimiento]]) -> 4 | P7: =SUMIF(Tabla3[Corregimiento],Tabla7[[#This Row],[Corregimiento]],Tabla3[VLR. TRANSPORTE]) -> 221000 | Q7: =AVERAGEIF(Tabla3[Corregimiento],Tabla7[[#This Row],[Corregimiento]],Tabla3[DISTANCIA (km)]) -> 18.542 | R7: =AVERAGEIF(Tabla3[Corregimiento],Tabla7[[#This Row],[Corregimiento]],Tabla3[Valor Tran]) -> 55250 | S7: =AVERAGEIF(Tabla8[Corregimiento],Tabla7[[#This Row],[Corregimiento]],Tabla8[Costo Total]) -> 91189.958 | T7: =AVERAGEIF(Tabla8[Corregimiento],Tabla7[[#This Row],[Corregimiento]],Tabla8[Perdida o ganancia de margen]) -> -0.074418547
A8: 45968 | B8: =COUNTIF(Tabla3[FECHA],Tabla4[[#This Row],[Fecha]]) -> 6 | C8: =SUMIF(Tabla3[FECHA],Tabla4[[#This Row],[Fecha]],Tabla3[VLR. TRANSPORTE]) -> 420000 | E8: Los bomberos | F8: =COUNTIF(Tabla3[LUGAR ENVÍO],Tabla6[[#This Row],[Nombre]]) -> 0 | G8: =SUMIF(Tabla3[LUGAR ENVÍO],Tabla6[[#This Row],[Nombre]],Tabla3[Numero de Transportes]) -> 0 | H8: =Tabla6[[#This Row],[Numero de Facturas]]/Tabla6[[#Totals],[Numero de Facturas]] -> 0 | I8: =SUMIF(Tabla3[LUGAR ENVÍO],Tabla6[[#This Row],[Nombre]],Tabla3[VLR. TRANSPORTE]) -> 0 | J8: =AVERAGEIF(Tabla3[LUGAR ENVÍO],Tabla6[[#This Row],[Nombre]],Tabla3[VLR. TRANSPORTE]) -> #DIV/0! | K8: =Tabla6[[#This Row],[Distancia total ida y vuelta]]/Tabla6[[#This Row],[Numero de Facturas]] -> #DIV/0! | L8: =SUMIF(Tabla3[LUGAR ENVÍO],Tabla6[[#This Row],[Nombre]],Tabla3[DISTANCIA (km)]) -> 0 | N8: El Palmar | O8: =COUNTIF(Tabla3[Corregimiento],Tabla7[[#This Row],[Corregimiento]]) -> 4 | P8: =SUMIF(Tabla3[Corregimiento],Tabla7[[#This Row],[Corregimiento]],Tabla3[VLR. TRANSPORTE]) -> 160000 | Q8: =AVERAGEIF(Tabla3[Corregimiento],Tabla7[[#This Row],[Corregimiento]],Tabla3[DISTANCIA (km)]) -> 4.35775 | R8: =AVERAGEIF(Tabla3[Corregimiento],Tabla7[[#This Row],[Corregimiento]],Tabla3[Valor Tran]) -> 40000 | S8: =AVERAGEIF(Tabla8[Corregimiento],Tabla7[[#This Row],[Corregimiento]],Tabla8[Costo Total]) -> 52078.104 | T8: =AVERAGEIF(Tabla8[Corregimiento],Tabla7[[#This Row],[Corregimiento]],Tabla8[Perdida o ganancia de margen]) -> -0.28020703
A9: 45969 | B9: =COUNTIF(Tabla3[FECHA],Tabla4[[#This Row],[Fecha]]) -> 7 | C9: =SUMIF(Tabla3[FECHA],Tabla4[[#This Row],[Fecha]],Tabla3[VLR. TRANSPORTE]) -> 245000 | E9: El Carmen | F9: =COUNTIF(Tabla3[LUGAR ENVÍO],Tabla6[[#This Row],[Nombre]]) -> 0 | G9: =SUMIF(Tabla3[LUGAR ENVÍO],Tabla6[[#This Row],[Nombre]],Tabla3[Numero de Transportes]) -> 0 | H9: =Tabla6[[#This Row],[Numero de Facturas]]/Tabla6[[#Totals],[Numero de Facturas]] -> 0 | I9: =SUMIF(Tabla3[LUGAR ENVÍO],Tabla6[[#This Row],[Nombre]],Tabla3[VLR. TRANSPORTE]) -> 0 | J9: =AVERAGEIF(Tabla3[LUGAR ENVÍO],Tabla6[[#This Row],[Nombre]],Tabla3[VLR. TRANSPORTE]) -> #DIV/0! | K9: =Tabla6[[#This Row],[Distancia total ida y vuelta]]/Tabla6[[#This Row],[Numero de Facturas]] -> #DIV/0! | L9: =SUMIF(Tabla3[LUGAR ENVÍO],Tabla6[[#This Row],[Nombre]],Tabla3[DISTANCIA (km)]) -> 0 | O9: =SUM(Tabla7[Total de transportes]) -> 240 | T9: =SUBTOTAL(101,Tabla7[Perdida promedio de margen]) -> -0.15335531
A10: 45970 | B10: =COUNTIF(Tabla3[FECHA],Tabla4[[#This Row],[Fecha]]) -> 1 | C10: =SUMIF(Tabla3[FECHA],Tabla4[[#This Row],[Fecha]],Tabla3[VLR. TRANSPORTE]) -> 60000 | E10: San Jose del Salado | F10: =COUNTIF(Tabla3[LUGAR ENVÍO],Tabla6[[#This Row],[Nombre]]) -> 7 | G10: =SUMIF(Tabla3[LUGAR ENVÍO],Tabla6[[#This Row],[Nombre]],Tabla3[Numero de Transportes]) -> 9 | H10: =Tabla6[[#This Row],[Numero de Facturas]]/Tabla6[[#Totals],[Numero de Facturas]] -> 0.10144928 | I10: =SUMIF(Tabla3[LUGAR ENVÍO],Tabla6[[#This Row],[Nombre]],Tabla3[VLR. TRANSPORTE]) -> 500000 | J10: =AVERAGEIF(Tabla3[LUGAR ENVÍO],Tabla6[[#This Row],[Nombre]],Tabla3[VLR. TRANSPORTE]) -> 71428.571 | K10: =Tabla6[[#This Row],[Distancia total ida y vuelta]]/Tabla6[[#This Row],[Numero de Facturas]] -> 13.07 | L10: =SUMIF(Tabla3[LUGAR ENVÍO],Tabla6[[#This Row],[Nombre]],Tabla3[DISTANCIA (km)]) -> 91.49 | O10: =COUNTIF(Tabla3[Corregimiento],Tabla7[[#This Row],[Corregimiento]]) -> 0 | P10: =SUMIF(Tabla3[Corregimiento],Tabla7[[#This Row],[Corregimiento]],Tabla3[VLR. TRANSPORTE]) -> 0 | Q10: =AVERAGEIF(Tabla3[Corregimiento],Tabla7[[#This Row],[Corregimiento]],Tabla3[DISTANCIA (km)]) -> #DIV/0! | R10: =AVERAGEIF(Tabla3[Corregimiento],Tabla7[[#This Row],[Corregimiento]],Tabla3[Valor Tran]) -> #DIV/0! | S10: =AVERAGEIF(Tabla8[Corregimiento],Tabla7[[#This Row],[Corregimiento]],Tabla8[Costo Total]) -> #DIV/0! | T10: =AVERAGEIF(Tabla8[Corregimiento],Tabla7[[#This Row],[Corregimiento]],Tabla8[Perdida o ganancia de margen]) -> #DIV/0!
A11: 45971 | B11: =COUNTIF(Tabla3[FECHA],Tabla4[[#This Row],[Fecha]]) -> 7 | C11: =SUMIF(Tabla3[FECHA],Tabla4[[#This Row],[Fecha]],Tabla3[VLR. TRANSPORTE]) -> 335000 | E11: El Bosque | F11: =COUNTIF(Tabla3[LUGAR ENVÍO],Tabla6[[#This Row],[Nombre]]) -> 0 | G11: =SUMIF(Tabla3[LUGAR ENVÍO],Tabla6[[#This Row],[Nombre]],Tabla3[Numero de Transportes]) -> 0 | H11: =Tabla6[[#This Row],[Numero de Facturas]]/Tabla6[[#Totals],[Numero de Facturas]] -> 0 | I11: =SUMIF(Tabla3[LUGAR ENVÍO],Tabla6[[#This Row],[Nombre]],Tabla3[VLR. TRANSPORTE]) -> 0 | J11: =AVERAGEIF(Tabla3[LUGAR ENVÍO],Tabla6[[#This Row],[Nombre]],Tabla3[VLR. TRANSPORTE]) -> #DIV/0! | K11: =Tabla6[[#This Row],[Distancia total ida y vuelta]]/Tabla6[[#This Row],[Numero de Facturas]] -> #DIV/0! | L11: =SUMIF(Tabla3[LUGAR ENVÍO],Tabla6[[#This Row],[Nombre]],Tabla3[DISTANCIA (km)]) -> 0
A12: 45972 | B12: =COUNTIF(Tabla3[FECHA],Tabla4[[#This Row],[Fecha]]) -> 6 | C12: =SUMIF(Tabla3[FECHA],Tabla4[[#This Row],[Fecha]],Tabla3[VLR. TRANSPORTE]) -> 295000 | E12: Parcelacion San Fernando | F12: =COUNTIF(Tabla3[LUGAR ENVÍO],Tabla6[[#This Row],[Nombre]]) -> 0 | G12: =SUMIF(Tabla3[LUGAR ENVÍO],Tabla6[[#This Row],[Nombre]],Tabla3[Numero de Transportes]) -> 0 | H12: =Tabla6[[#This Row],[Numero de Facturas]]/Tabla6[[#Totals],[Numero de Facturas]] -> 0 | I12: =SUMIF(Tabla3[LUGAR ENVÍO],Tabla6[[#This Row],[Nombre]],Tabla3[VLR. TRANSPORTE]) -> 0 | J12: =AVERAGEIF(Tabla3[LUGAR ENVÍO],Tabla6[[#This Row],[Nombre]],Tabla3[VLR. TRANSPORTE]) -> #DIV/0! | K12: =Tabla6[[#This Row],[Distancia total ida y vuelta]]/Tabla6[[#This Row],[Numero de Facturas]] -> #DIV/0! | L12: =SUMIF(Tabla3[LUGAR ENVÍO],Tabla6[[#This Row],[Nombre]],Tabla3[DISTANCIA (km)]) -> 0
A13: 45973 | B13: =COUNTIF(Tabla3[FECHA],Tabla4[[#This Row],[Fecha]]) -> 7 | C13: =SUMIF(Tabla3[FECHA],Tabla4[[#This Row],[Fecha]],Tabla3[VLR. TRANSPORTE]) -> 480000 | E13: La Zulia 2 | F13: =COUNTIF(Tabla3[LUGAR ENVÍO],Tabla6[[#This Row],[Nombre]]) -> 0 | G13: =SUMIF(Tabla3[LUGAR ENVÍO],Tabla6[[#This Row],[Nombre]],Tabla3[Numero de Transportes]) -> 0 | H13: =Tabla6[[#This Row],[Numero de Facturas]]/Tabla6[[#Totals],[Numero de Facturas]] -> 0 | I13: =SUMIF(Tabla3[LUGAR ENVÍO],Tabla6[[#This Row],[Nombre]],Tabla3[VLR. TRANSPORTE]) -> 0 | J13: =AVERAGEIF(Tabla3[LUGAR ENVÍO],Tabla6[[#This Row],[Nombre]],Tabla3[VLR. TRANSPORTE]) -> #DIV/0! | K13: =Tabla6[[#This Row],[Distancia total ida y vuelta]]/Tabla6[[#This Row],[Numero de Facturas]] -> #DIV/0! | L13: =SUMIF(Tabla3[LUGAR ENVÍO],Tabla6[[#This Row],[Nombre]],Tabla3[DISTANCIA (km)]) -> 0
A14: 45974 | B14: =COUNTIF(Tabla3[FECHA],Tabla4[[#This Row],[Fecha]]) -> 14 | C14: =SUMIF(Tabla3[FECHA],Tabla4[[#This Row],[Fecha]],Tabla3[VLR. TRANSPORTE]) -> 490000 | E14: Chipre | F14: =COUNTIF(Tabla3[LUGAR ENVÍO],Tabla6[[#This Row],[Nombre]]) -> 3 | G14: =SUMIF(Tabla3[LUGAR ENVÍO],Tabla6[[#This Row],[Nombre]],Tabla3[Numero de Transportes]) -> 4 | H14: =Tabla6[[#This Row],[Numero de Facturas]]/Tabla6[[#Totals],[Numero de Facturas]] -> 0.043478261 | I14: =SUMIF(Tabla3[LUGAR ENVÍO],Tabla6[[#This Row],[Nombre]],Tabla3[VLR. TRANSPORTE]) -> 165000 | J14: =AVERAGEIF(Tabla3[LUGAR ENVÍO],Tabla6[[#This Row],[Nombre]],Tabla3[VLR. TRANSPORTE]) -> 55000 | K14: =Tabla6[[#This Row],[Distancia total ida y vuelta]]/Tabla6[[#This Row],[Numero de Facturas]] -> 4.781 | L14: =SUMIF(Tabla3[LUGAR ENVÍO],Tabla6[[#This Row],[Nombre]],Tabla3[DISTANCIA (km)]) -> 14.343
A15: 45975 | B15: =COUNTIF(Tabla3[FECHA],Tabla4[[#This Row],[Fecha]]) -> 4 | C15: =SUMIF(Tabla3[FECHA],Tabla4[[#This Row],[Fecha]],Tabla3[VLR. TRANSPORTE]) -> 165000 | E15: Monteredondo | F15: =COUNTIF(Tabla3[LUGAR ENVÍO],Tabla6[[#This Row],[Nombre]]) -> 5 | G15: =SUMIF(Tabla3[LUGAR ENVÍO],Tabla6[[#This Row],[Nombre]],Tabla3[Numero de Transportes]) -> 6 | H15: =Tabla6[[#This Row],[Numero de Facturas]]/Tabla6[[#Totals],[Numero de Facturas]] -> 0.072463768 | I15: =SUMIF(Tabla3[LUGAR ENVÍO],Tabla6[[#This Row],[Nombre]],Tabla3[VLR. TRANSPORTE]) -> 150000 | J15: =AVERAGEIF(Tabla3[LUGAR ENVÍO],Tabla6[[#This Row],[Nombre]],Tabla3[VLR. TRANSPORTE]) -> 30000 | K15: =Tabla6[[#This Row],[Distancia total ida y vuelta]]/Tabla6[[#This Row],[Numero de Facturas]] -> 0.428 | L15: =SUMIF(Tabla3[LUGAR ENVÍO],Tabla6[[#This Row],[Nombre]],Tabla3[DISTANCIA (km)]) -> 2.14
A16: 45976 | B16: =COUNTIF(Tabla3[FECHA],Tabla4[[#This Row],[Fecha]]) -> 7 | C16: =SUMIF(Tabla3[FECHA],Tabla4[[#This Row],[Fecha]],Tabla3[VLR. TRANSPORTE]) -> 370000 | E16: Agua Sucia | F16: =COUNTIF(Tabla3[LUGAR ENVÍO],Tabla6[[#This Row],[Nombre]]) -> 0 | G16: =SUMIF(Tabla3[LUGAR ENVÍO],Tabla6[[#This Row],[Nombre]],Tabla3[Numero de Transportes]) -> 0 | H16: =Tabla6[[#This Row],[Numero de Facturas]]/Tabla6[[#Totals],[Numero de Facturas]] -> 0 | I16: =SUMIF(Tabla3[LUGAR ENVÍO],Tabla6[[#This Row],[Nombre]],Tabla3[VLR. TRANSPORTE]) -> 0 | J16: =AVERAGEIF(Tabla3[LUGAR ENVÍO],Tabla6[[#This Row],[Nombre]],Tabla3[VLR. TRANSPORTE]) -> #DIV/0! | K16: =Tabla6[[#This Row],[Distancia total ida y vuelta]]/Tabla6[[#This Row],[Numero de Facturas]] -> #DIV/0! | L16: =SUMIF(Tabla3[LUGAR ENVÍO],Tabla6[[#This Row],[Nombre]],Tabla3[DISTANCIA (km)]) -> 0
A17: 45977 | B17: =COUNTIF(Tabla3[FECHA],Tabla4[[#This Row],[Fecha]]) -> 1 | C17: =SUMIF(Tabla3[FECHA],Tabla4[[#This Row],[Fecha]],Tabla3[VLR. TRANSPORTE]) -> 25000 | E17: Tocota | F17: =COUNTIF(Tabla3[LUGAR ENVÍO],Tabla6[[#This Row],[Nombre]]) -> 5 | G17: =SUMIF(Tabla3[LUGAR ENVÍO],Tabla6[[#This Row],[Nombre]],Tabla3[Numero de Transportes]) -> 6 | H17: =Tabla6[[#This Row],[Numero de Facturas]]/Tabla6[[#Totals],[Numero de Facturas]] -> 0.072463768 | I17: =SUMIF(Tabla3[LUGAR ENVÍO],Tabla6[[#This Row],[Nombre]],Tabla3[VLR. TRANSPORTE]) -> 290000 | J17: =AVERAGEIF(Tabla3[LUGAR ENVÍO],Tabla6[[#This Row],[Nombre]],Tabla3[VLR. TRANSPORTE]) -> 58000 | K17: =Tabla6[[#This Row],[Distancia total ida y vuelta]]/Tabla6[[#This Row],[Numero de Facturas]] -> 9.438 | L17: =SUMIF(Tabla3[LUGAR ENVÍO],Tabla6[[#This Row],[Nombre]],Tabla3[DISTANCIA (km)]) -> 47.19
A18: 45978 | B18: =COUNTIF(Tabla3[FECHA],Tabla4[[#This Row],[Fecha]]) -> 7 | C18: =SUMIF(Tabla3[FECHA],Tabla4[[#This Row],[Fecha]],Tabla3[VLR. TRANSPORTE]) -> 550000 | E18: Altos tortolas | F18: =COUNTIF(Tabla3[LUGAR ENVÍO],Tabla6[[#This Row],[Nombre]]) -> 0 | G18: =SUMIF(Tabla3[LUGAR ENVÍO],Tabla6[[#This Row],[Nombre]],Tabla3[Numero de Transportes]) -> 0 | H18: =Tabla6[[#This Row],[Numero de Facturas]]/Tabla6[[#Totals],[Numero de Facturas]] -> 0 | I18: =SUMIF(Tabla3[LUGAR ENVÍO],Tabla6[[#This Row],[Nombre]],Tabla3[VLR. TRANSPORTE]) -> 0 | J18: =AVERAGEIF(Tabla3[LUGAR ENVÍO],Tabla6[[#This Row],[Nombre]],Tabla3[VLR. TRANSPORTE]) -> #DIV/0! | K18: =Tabla6[[#This Row],[Distancia total ida y vuelta]]/Tabla6[[#This Row],[Numero de Facturas]] -> #DIV/0! | L18: =SUMIF(Tabla3[LUGAR ENVÍO],Tabla6[[#This Row],[Nombre]],Tabla3[DISTANCIA (km)]) -> 0
A19: 45979 | B19: =COUNTIF(Tabla3[FECHA],Tabla4[[#This Row],[Fecha]]) -> 6 | C19: =SUMIF(Tabla3[FECHA],Tabla4[[#This Row],[Fecha]],Tabla3[VLR. TRANSPORTE]) -> 535000 | E19: El Carmelo | F19: =COUNTIF(Tabla3[LUGAR ENVÍO],Tabla6[[#This Row],[Nombre]]) -> 0 | G19: =SUMIF(Tabla3[LUGAR ENVÍO],Tabla6[[#This Row],[Nombre]],Tabla3[Numero de Transportes]) -> 0 | H19: =Tabla6[[#This Row],[Numero de Facturas]]/Tabla6[[#Totals],[Numero de Facturas]] -> 0 | I19: =SUMIF(Tabla3[LUGAR ENVÍO],Tabla6[[#This Row],[Nombre]],Tabla3[VLR. TRANSPORTE]) -> 0 | J19: =AVERAGEIF(Tabla3[LUGAR ENVÍO],Tabla6[[#This Row],[Nombre]],Tabla3[VLR. TRANSPORTE]) -> #DIV/0! | K19: =Tabla6[[#This Row],[Distancia total ida y vuelta]]/Tabla6[[#This Row],[Numero de Facturas]] -> #DIV/0! | L19: =SUMIF(Tabla3[LUGAR ENVÍO],Tabla6[[#This Row],[Nombre]],Tabla3[DISTANCIA (km)]) -> 0
A20: 45980 | B20: =COUNTIF(Tabla3[FECHA],Tabla4[[#This Row],[Fecha]]) -> 4 | C20: =SUMIF(Tabla3[FECHA],Tabla4[[#This Row],[Fecha]],Tabla3[VLR. TRANSPORTE]) -> 160000 | E20: KM 40 | F20: =COUNTIF(Tabla3[LUGAR ENVÍO],Tabla6[[#This Row],[Nombre]]) -> 0 | G20: =SUMIF(Tabla3[LUGAR ENVÍO],Tabla6[[#This Row],[Nombre]],Tabla3[Numero de Transportes]) -> 0 | H20: =Tabla6[[#This Row],[Numero de Facturas]]/Tabla6[[#Totals],[Numero de Facturas]] -> 0 | I20: =SUMIF(Tabla3[LUGAR ENVÍO],Tabla6[[#This Row],[Nombre]],Tabla3[VLR. TRANSPORTE]) -> 0 | J20: =AVERAGEIF(Tabla3[LUGAR ENVÍO],Tabla6[[#This Row],[Nombre]],Tabla3[VLR. TRANSPORTE]) -> #DIV/0! | K20: =Tabla6[[#This Row],[Distancia total ida y vuelta]]/Tabla6[[#This Row],[Numero de Facturas]] -> #DIV/0! | L20: =SUMIF(Tabla3[LUGAR ENVÍO],Tabla6[[#This Row],[Nombre]],Tabla3[DISTANCIA (km)]) -> 0
A21: 45981 | B21: =COUNTIF(Tabla3[FECHA],Tabla4[[#This Row],[Fecha]]) -> 13 | C21: =SUMIF(Tabla3[FECHA],Tabla4[[#This Row],[Fecha]],Tabla3[VLR. TRANSPORTE]) -> 625000 | E21: Parcelación Monte Rico | F21: =COUNTIF(Tabla3[LUGAR ENVÍO],Tabla6[[#This Row],[Nombre]]) -> 0 | G21: =SUMIF(Tabla3[LUGAR ENVÍO],Tabla6[[#This Row],[Nombre]],Tabla3[Numero de Transportes]) -> 0 | H21: =Tabla6[[#This Row],[Numero de Facturas]]/Tabla6[[#Totals],[Numero de Facturas]] -> 0 | I21: =SUMIF(Tabla3[LUGAR ENVÍO],Tabla6[[#This Row],[Nombre]],Tabla3[VLR. TRANSPORTE]) -> 0 | J21: =AVERAGEIF(Tabla3[LUGAR ENVÍO],Tabla6[[#This Row],[Nombre]],Tabla3[VLR. TRANSPORTE]) -> #DIV/0! | K21: =Tabla6[[#This Row],[Distancia total ida y vuelta]]/Tabla6[[#This Row],[Numero de Facturas]] -> #DIV/0! | L21: =SUMIF(Tabla3[LUGAR ENVÍO],Tabla6[[#This Row],[Nombre]],Tabla3[DISTANCIA (km)]) -> 0
A22: 45982 | B22: =COUNTIF(Tabla3[FECHA],Tabla4[[#This Row],[Fecha]]) -> 11 | C22: =SUMIF(Tabla3[FECHA],Tabla4[[#This Row],[Fecha]],Tabla3[VLR. TRANSPORTE]) -> 571000 | E22: El Diviso | F22: =COUNTIF(Tabla3[LUGAR ENVÍO],Tabla6[[#This Row],[Nombre]]) -> 0 | G22: =SUMIF(Tabla3[LUGAR ENVÍO],Tabla6[[#This Row],[Nombre]],Tabla3[Numero de Transportes]) -> 0 | H22: =Tabla6[[#This Row],[Numero de Facturas]]/Tabla6[[#Totals],[Numero de Facturas]] -> 0 | I22: =SUMIF(Tabla3[LUGAR ENVÍO],Tabla6[[#This Row],[Nombre]],Tabla3[VLR. TRANSPORTE]) -> 0 | J22: =AVERAGEIF(Tabla3[LUGAR ENVÍO],Tabla6[[#This Row],[Nombre]],Tabla3[VLR. TRANSPORTE]) -> #DIV/0! | K22: =Tabla6[[#This Row],[Distancia total ida y vuelta]]/Tabla6[[#This Row],[Numero de Facturas]] -> #DIV/0! | L22: =SUMIF(Tabla3[LUGAR ENVÍO],Tabla6[[#This Row],[Nombre]],Tabla3[DISTANCIA (km)]) -> 0
... A31: 45991 | B31: =COUNTIF(Tabla3[FECHA],Tabla4[[#This Row],[Fecha]]) -> 4 | C31: =SUMIF(Tabla3[FECHA],Tabla4[[#This Row],[Fecha]],Tabla3[VLR. TRANSPORTE]) -> 160000 | E31: Tierras blancas | F31: =COUNTIF(Tabla3[LUGAR ENVÍO],Tabla6[[#This Row],[Nombre]]) -> 0 | G31: =SUMIF(Tabla3[LUGAR ENVÍO],Tabla6[[#This Row],[Nombre]],Tabla3[Numero de Transportes]) -> 0 | H31: =Tabla6[[#This Row],[Numero de Facturas]]/Tabla6[[#Totals],[Numero de Facturas]] -> 0 | I31: =SUMIF(Tabla3[LUGAR ENVÍO],Tabla6[[#This Row],[Nombre]],Tabla3[VLR. TRANSPORTE]) -> 0 | J31: =AVERAGEIF(Tabla3[LUGAR ENVÍO],Tabla6[[#This Row],[Nombre]],Tabla3[VLR. TRANSPORTE]) -> #DIV/0! | K31: =Tabla6[[#This Row],[Distancia total ida y vuelta]]/Tabla6[[#This Row],[Numero de Facturas]] -> #DIV/0! | L31: =SUMIF(Tabla3[LUGAR ENVÍO],Tabla6[[#This Row],[Nombre]],Tabla3[DISTANCIA (km)]) -> 0
B32: =SUBTOTAL(109,Tabla4[Total de envios]) -> 216 | C32: =SUBTOTAL(109,Tabla4[Valor]) -> 11466000 | E32: Pa la chingada | F32: =COUNTIF(Tabla3[LUGAR ENVÍO],Tabla6[[#This Row],[Nombre]]) -> 0 | G32: =SUMIF(Tabla3[LUGAR ENVÍO],Tabla6[[#This Row],[Nombre]],Tabla3[Numero de Transportes]) -> 0 | H32: =Tabla6[[#This Row],[Numero de Facturas]]/Tabla6[[#Totals],[Numero de Facturas]] -> 0 | I32: =SUMIF(Tabla3[LUGAR ENVÍO],Tabla6[[#This Row],[Nombre]],Tabla3[VLR. TRANSPORTE]) -> 0 | J32: =AVERAGEIF(Tabla3[LUGAR ENVÍO],Tabla6[[#This Row],[Nombre]],Tabla3[VLR. TRANSPORTE]) -> #DIV/0! | K32: =Tabla6[[#This Row],[Distancia total ida y vuelta]]/Tabla6[[#This Row],[Numero de Facturas]] -> #DIV/0! | L32: =SUMIF(Tabla3[LUGAR ENVÍO],Tabla6[[#This Row],[Nombre]],Tabla3[DISTANCIA (km)]) -> 0
E33: Cositas ricas | F33: =COUNTIF(Tabla3[LUGAR ENVÍO],Tabla6[[#This Row],[Nombre]]) -> 0 | G33: =SUMIF(Tabla3[LUGAR ENVÍO],Tabla6[[#This Row],[Nombre]],Tabla3[Numero de Transportes]) -> 0 | H33: =Tabla6[[#This Row],[Numero de Facturas]]/Tabla6[[#Totals],[Numero de Facturas]] -> 0 | I33: =SUMIF(Tabla3[LUGAR ENVÍO],Tabla6[[#This Row],[Nombre]],Tabla3[VLR. TRANSPORTE]) -> 0 | J33: =AVERAGEIF(Tabla3[LUGAR ENVÍO],Tabla6[[#This Row],[Nombre]],Tabla3[VLR. TRANSPORTE]) -> #DIV/0! | K33: =Tabla6[[#This Row],[Distancia total ida y vuelta]]/Tabla6[[#This Row],[Numero de Facturas]] -> #DIV/0! | L33: =SUMIF(Tabla3[LUGAR ENVÍO],Tabla6[[#This Row],[Nombre]],Tabla3[DISTANCIA (km)]) -> 0
E34: KM 25 | F34: =COUNTIF(Tabla3[LUGAR ENVÍO],Tabla6[[#This Row],[Nombre]]) -> 2 | G34: =SUMIF(Tabla3[LUGAR ENVÍO],Tabla6[[#This Row],[Nombre]],Tabla3[Numero de Transportes]) -> 2 | H34: =Tabla6[[#This Row],[Numero de Facturas]]/Tabla6[[#Totals],[Numero de Facturas]] -> 0.028985507 | I34: =SUMIF(Tabla3[LUGAR ENVÍO],Tabla6[[#This Row],[Nombre]],Tabla3[VLR. TRANSPORTE]) -> 110000 | J34: =AVERAGEIF(Tabla3[LUGAR ENVÍO],Tabla6[[#This Row],[Nombre]],Tabla3[VLR. TRANSPORTE]) -> 55000 | K34: =Tabla6[[#This Row],[Distancia total ida y vuelta]]/Tabla6[[#This Row],[Numero de Facturas]] -> 6.46658 | L34: =SUMIF(Tabla3[LUGAR ENVÍO],Tabla6[[#This Row],[Nombre]],Tabla3[DISTANCIA (km)]) -> 12.93316
E35: El Queremal | F35: =COUNTIF(Tabla3[LUGAR ENVÍO],Tabla6[[#This Row],[Nombre]]) -> 4 | G35: =SUMIF(Tabla3[LUGAR ENVÍO],Tabla6[[#This Row],[Nombre]],Tabla3[Numero de Transportes]) -> 4 | H35: =Tabla6[[#This Row],[Numero de Facturas]]/Tabla6[[#Totals],[Numero de Facturas]] -> 0.057971014 | I35: =SUMIF(Tabla3[LUGAR ENVÍO],Tabla6[[#This Row],[Nombre]],Tabla3[VLR. TRANSPORTE]) -> 221000 | J35: =AVERAGEIF(Tabla3[LUGAR ENVÍO],Tabla6[[#This Row],[Nombre]],Tabla3[VLR. TRANSPORTE]) -> 55250 | K35: =Tabla6[[#This Row],[Distancia total ida y vuelta]]/Tabla6[[#This Row],[Numero de Facturas]] -> 18.542 | L35: =SUMIF(Tabla3[LUGAR ENVÍO],Tabla6[[#This Row],[Nombre]],Tabla3[DISTANCIA (km)]) -> 74.168
F36: =SUBTOTAL(109,Tabla6[Numero de Facturas]) -> 69 | G36: =SUBTOTAL(109,Tabla6[Numero de envios]) -> 81 | I36: =SUBTOTAL(109,Tabla6[Valor envio]) -> 4271000 | K36: =SUBTOTAL(101,Tabla6[Distancia (KM)]) -> #DIV/0! | L36: =SUBTOTAL(101,Tabla6[Distancia total ida y vuelta]) -> 12.522564
E38: Nombre | F38: Numero de Facturas | G38: Numero de envios | H38: % | I38: Valor envio | J38: Promedio | K38: Distancia (KM)
E39: Parcelación Pirineos | F39: 8 | G39: 8 | H39: 0.0777 | I39: 350000 | J39: 43750 | K39: 2.66
E40: El Coscorron | F40: 7 | G40: 9 | H40: 0.068 | I40: 560000 | J40: 80000 | K40: 2.65
E41: Tortolas | F41: 7 | G41: 8 | H41: 0.068 | I41: 580000 | J41: 82857.14 | K41: 4.935
E42: KM 34 | F42: 7 | G42: 9 | H42: 0.068 | I42: 310000 | J42: 44285.71 | K42: 3.699
E43: Altos del Carmen | F43: 9 | G43: 9 | H43: 0.0874 | I43: 460000 | J43: 51111.11 | K43: 3.643
E44: Parcelacion la Cristalina | F44: 5 | G44: 5 | H44: 0.0485 | I44: 236000 | J44: 47200 | K44: 2.71
E45: Los bomberos | F45: 4 | G45: 5 | H45: 0.0388 | I45: 145000 | J45: 36250 | K45: 2.092
E46: El Carmen | F46: 4 | G46: 4 | H46: 0.0388 | I46: 170000 | J46: 42500 | K46: 4.201
E47: San Jose del Salado | F47: 6 | G47: 7 | H47: 0.0583 | I47: 380000 | J47: 63333.33 | K47: 8.714
E48: El Bosque | F48: 3 | G48: 3 | H48: 0.0291 | I48: 180000 | J48: 60000 | K48: 4.443
E49: Parcelacion San Fernando | F49: 3 | G49: 3 | H49: 0.0291 | I49: 160000 | J49: 53333.33 | K49: 7.6
...

Sheet Base de datos
A1: N° FACTURA | B1: FECHA | C1: TIPO FACTURA | D1: CLIENTE | E1: LUGAR ENVÍO | F1: ID | G1: Corregimiento | H1: DISTANCIA (km) | I1: Valor del transporte/KM | J1: PESO EST. (kg) | K1: Numero de Transportes | L1: VLR. TRANSPORTE | M1: Valor Tran | N1: VLR. TOTAL FACT. | O1: VLR. PRODUCTOS | P1: Local/Tercero (1/0) | Q1: FORMA PAGO
A2: 58563 | B2: 45978 | C2: sai | D2: Elizabeth Perlaza | E2: Villahermosa | F2: 6 | G2: =_xlfn.XLOOKUP(Tabla3[[#This Row],[ID]],Tabla2[ID],Tabla2[Corregimiento],"NA") -> El Limonar | H2: =_xlfn.XLOOKUP(Tabla3[[#This Row],[LUGAR ENVÍO]],Tabla9[[Nombre ]],Tabla9[Distancia],"NA") -> 6.788 | I2: =Tabla3[[#This Row],[Valor Tran]]/(Tabla3[[#This Row],[DISTANCIA (km)]]*2) -> 7365.9399 | K2: 2 | L2: 200000 | M2: =Tabla3[[#This Row],[VLR. TRANSPORTE]]/Tabla3[[#This Row],[Numero de Transportes]] -> 100000 | N2: 1044500 | O2: =Tabla3[[#This Row],[VLR. TOTAL FACT.]]-Tabla3[[#This Row],[VLR. TRANSPORTE]] -> 844500 | P2: 1 | Q2: Multiples
A3: 58646 | B3: 45983 | C3: sai | D3: jhon alex | E3: Villahermosa | F3: 6 | G3: =_xlfn.XLOOKUP(Tabla3[[#This Row],[ID]],Tabla2[ID],Tabla2[Corregimiento],"NA") -> El Limonar | H3: =_xlfn.XLOOKUP(Tabla3[[#This Row],[LUGAR ENVÍO]],Tabla9[[Nombre ]],Tabla9[Distancia],"NA") -> 6.788 | I3: =Tabla3[[#This Row],[Valor Tran]]/(Tabla3[[#This Row],[DISTANCIA (km)]]*2) -> 3682.9699 | K3: 1 | L3: 50000 | M3: =Tabla3[[#This Row],[VLR. TRANSPORTE]]/Tabla3[[#This Row],[Numero de Transportes]] -> 50000 | N3: 4067000 | O3: =Tabla3[[#This Row],[VLR. TOTAL FACT.]]-Tabla3[[#This Row],[VLR. TRANSPORTE]] -> 4017000 | P3: 1 | Q3: efectivo
A4: 47037 | B4: 45969 | C4: sai | D4: NA | E4: Villa saman | F4: 2 | G4: =_xlfn.XLOOKUP(Tabla3[[#This Row],[ID]],Tabla2[ID],Tabla2[Corregimiento],"NA") -> Borrero Ayerbe | H4: =_xlfn.XLOOKUP(Tabla3[[#This Row],[LUGAR ENVÍO]],Tabla9[[Nombre ]],Tabla9[Distancia],"NA") -> 2.059 | I4: =Tabla3[[#This Row],[Valor Tran]]/(Tabla3[[#This Row],[DISTANCIA (km)]]*2) -> 6070.9082 | K4: 1 | L4: 25000 | M4: =Tabla3[[#This Row],[VLR. TRANSPORTE]]/Tabla3[[#This Row],[Numero de Transportes]] -> 25000 | N4: 175000 | O4: =Tabla3[[#This Row],[VLR. TOTAL FACT.]]-Tabla3[[#This Row],[VLR. TRANSPORTE]] -> 150000 | P4: 0 | Q4: transferencia
A5: 58690 | B5: 45993 | C5: sai | D5: Carlos Torres | E5: Villa saman | F5: 2 | G5: =_xlfn.XLOOKUP(Tabla3[[#This Row],[ID]],Tabla2[ID],Tabla2[Corregimiento],"NA") -> Borrero Ayerbe | H5: =_xlfn.XLOOKUP(Tabla3[[#This Row],[LUGAR ENVÍO]],Tabla9[[Nombre ]],Tabla9[Distancia],"NA") -> 2.059 | I5: =Tabla3[[#This Row],[Valor Tran]]/(Tabla3[[#This Row],[DISTANCIA (km)]]*2) -> 4856.7266 | K5: 2 | L5: 40000 | M5: =Tabla3[[#This Row],[VLR. TRANSPORTE]]/Tabla3[[#This Row],[Numero de Transportes]] -> 20000 | N5: 387000 | O5: =Tabla3[[#This Row],[VLR. TOTAL FACT.]]-Tabla3[[#This Row],[VLR. TRANSPORTE]] -> 347000 | P5: 1 | Q5: efectivo
A6: 58823 | B6: 46000 | C6: manual | D6: miriam gomez | E6: Villa saman | F6: 2 | G6: =_xlfn.XLOOKUP(Tabla3[[#This Row],[ID]],Tabla2[ID],Tabla2[Corregimiento],"NA") -> Borrero Ayerbe | H6: =_xlfn.XLOOKUP(Tabla3[[#This Row],[LUGAR ENVÍO]],Tabla9[[Nombre ]],Tabla9[Distancia],"NA") -> 2.059 | I6: =Tabla3[[#This Row],[Valor Tran]]/(Tabla3[[#This Row],[DISTANCIA (km)]]*2) -> 3642.5449 | K6: 1 | L6: 15000 | M6: =Tabla3[[#This Row],[VLR. TRANSPORTE]]/Tabla3[[#This Row],[Numero de Transportes]] -> 15000 | N6: 2954000 | O6: =Tabla3[[#This Row],[VLR. TOTAL FACT.]]-Tabla3[[#This Row],[VLR. TRANSPORTE]] -> 2939000 | P6: 1 | Q6: efectivo
A7: 46418 | B7: 45962 | C7: sai | D7: katherine | E7: Villa emilia | F7: 4 | G7: =_xlfn.XLOOKUP(Tabla3[[#This Row],[ID]],Tabla2[ID],Tabla2[Corregimiento],"NA") -> El Carmen | H7: =_xlfn.XLOOKUP(Tabla3[[#This Row],[LUGAR ENVÍO]],Tabla9[[Nombre ]],Tabla9[Distancia],"NA") -> 3.449 | I7: =Tabla3[[#This Row],[Valor Tran]]/(Tabla3[[#This Row],[DISTANCIA (km)]]*2) -> 5798.7823 | K7: 1 | L7: 40000 | M7: =Tabla3[[#This Row],[VLR. TRANSPORTE]]/Tabla3[[#This Row],[Numero de Transportes]] -> 40000 | N7: 233000 | O7: =Tabla3[[#This Row],[VLR. TOTAL FACT.]]-Tabla3[[#This Row],[VLR. TRANSPORTE]] -> 193000 | P7: 0 | Q7: transferencia
A8: 48240 | B8: 2025-11-20 | C8: sai | D8: Amparo Rodriguez | E8: villa del toro | F8: 4 | G8: =_xlfn.XLOOKUP(Tabla3[[#This Row],[ID]],Tabla2[ID],Tabla2[Corregimiento],"NA") -> El Carmen | H8: =_xlfn.XLOOKUP(Tabla3[[#This Row],[LUGAR ENVÍO]],Tabla9[[Nombre ]],Tabla9[Distancia],"NA") -> 2.279762 | I8: =Tabla3[[#This Row],[Valor Tran]]/(Tabla3[[#This Row],[DISTANCIA (km)]]*2) -> 8772.8456 | K8: 1 | L8: 40000 | M8: 40000 | N8: 410500 | O8: =Tabla3[[#This Row],[VLR. TOTAL FACT.]]-Tabla3[[#This Row],[VLR. TRANSPORTE]] -> 370500 | P8: 1 | Q8: tarjeta
A9: 48122 | B9: 2025-11-12 | C9: sai | D9: Oscar Narvaez | E9: villa del toro | F9: 4 | G9: =_xlfn.XLOOKUP(Tabla3[[#This Row],[ID]],Tabla2[ID],Tabla2[Corregimiento],"NA") -> El Carmen | H9: =_xlfn.XLOOKUP(Tabla3[[#This Row],[LUGAR ENVÍO]],Tabla9[[Nombre ]],Tabla9[Distancia],"NA") -> 2.279762 | I9: =Tabla3[[#This Row],[Valor Tran]]/(Tabla3[[#This Row],[DISTANCIA (km)]]*2) -> 8772.8456 | K9: 1 | L9: 40000 | M9: 40000 | N9: 412700 | O9: =Tabla3[[#This Row],[VLR. TOTAL FACT.]]-Tabla3[[#This Row],[VLR. TRANSPORTE]] -> 372700 | P9: 1 | Q9: transferencia
A10: 55590 | B10: 2025-11-13 | C10: sai | D10: Olga Patricia | E10: villa del toro | F10: 4 | G10: =_xlfn.XLOOKUP(Tabla3[[#This Row],[ID]],Tabla2[ID],Tabla2[Corregimiento],"NA") -> El Carmen | H10: =_xlfn.XLOOKUP(Tabla3[[#This Row],[LUGAR ENVÍO]],Tabla9[[Nombre ]],Tabla9[Distancia],"NA") -> 2.279762 | I10: =Tabla3[[#This Row],[Valor Tran]]/(Tabla3[[#This Row],[DISTANCIA (km)]]*2) -> 8772.8456 | K10: 1 | L10: 40000 | M10: 40000 | N10: 437200 | O10: =Tabla3[[#This Row],[VLR. TOTAL FACT.]]-Tabla3[[#This Row],[VLR. TRANSPORTE]] -> 397200 | P10: 1 | Q10: efectivo
A11: 49737 | B11: 2025-11-26 | C11: sai | D11: Tania Duque | E11: villa del toro | F11: 4 | G11: =_xlfn.XLOOKUP(Tabla3[[#This Row],[ID]],Tabla2[ID],Tabla2[Corregimiento],"NA") -> El Carmen | H11: =_xlfn.XLOOKUP(Tabla3[[#This Row],[LUGAR ENVÍO]],Tabla9[[Nombre ]],Tabla9[Distancia],"NA") -> 2.279762 | I11: =Tabla3[[#This Row],[Valor Tran]]/(Tabla3[[#This Row],[DISTANCIA (km)]]*2) -> 9869.4513 | K11: 1 | L11: 45000 | M11: 45000 | N11: 443600 | O11: =Tabla3[[#This Row],[VLR. TOTAL FACT.]]-Tabla3[[#This Row],[VLR. TRANSPORTE]] -> 398600 | P11: 1 | Q11: tarjeta
A12: 47087 | B12: 45966 | C12: sai | D12: isabel castaño | E12: villa del toro | F12: 4 | G12: =_xlfn.XLOOKUP(Tabla3[[#This Row],[ID]],Tabla2[ID],Tabla2[Corregimiento],"NA") -> El Carmen | H12: =_xlfn.XLOOKUP(Tabla3[[#This Row],[LUGAR ENVÍO]],Tabla9[[Nombre ]],Tabla9[Distancia],"NA") -> 2.279762 | I12: =Tabla3[[#This Row],[Valor Tran]]/(Tabla3[[#This Row],[DISTANCIA (km)]]*2) -> 8772.8456 | K12: 1 | L12: 40000 | M12: =Tabla3[[#This Row],[VLR. TRANSPORTE]]/Tabla3[[#This Row],[Numero de Transportes]] -> 40000 | N12: 450100 | O12: =Tabla3[[#This Row],[VLR. TOTAL FACT.]]-Tabla3[[#This Row],[VLR. TRANSPORTE]] -> 410100 | P12: 1 | Q12: tarjeta
A13: 34670 | B13: 2025-11-11 | C13: manual | D13: Esperanza Ortega | E13: villa del toro | F13: 4 | G13: =_xlfn.XLOOKUP(Tabla3[[#This Row],[ID]],Tabla2[ID],Tabla2[Corregimiento],"NA") -> El Carmen | H13: =_xlfn.XLOOKUP(Tabla3[[#This Row],[LUGAR ENVÍO]],Tabla9[[Nombre ]],Tabla9[Distancia],"NA") -> 2.279762 | I13: =Tabla3[[#This Row],[Valor Tran]]/(Tabla3[[#This Row],[DISTANCIA (km)]]*2) -> 8772.8456 | K13: 1 | L13: 40000 | M13: 40000 | N13: 479900 | O13: =Tabla3[[#This Row],[VLR. TOTAL FACT.]]-Tabla3[[#This Row],[VLR. TRANSPORTE]] -> 439900 | P13: 1 | Q13: efectivo
A14: 30518 | B14: 45974 | C14: manual | D14: martha rosero | E14: Tortolas | F14: 4 | G14: =_xlfn.XLOOKUP(Tabla3[[#This Row],[ID]],Tabla2[ID],Tabla2[Corregimiento],"NA") -> El Carmen | H14: =_xlfn.XLOOKUP(Tabla3[[#This Row],[LUGAR ENVÍO]],Tabla9[[Nombre ]],Tabla9[Distancia],"NA") -> 5.757 | I14: =Tabla3[[#This Row],[Valor Tran]]/(Tabla3[[#This Row],[DISTANCIA (km)]]*2) -> 3474.0316 | K14: 1 | L14: 40000 | M14: =Tabla3[[#This Row],[VLR. TRANSPORTE]]/Tabla3[[#This Row],[Numero de Transportes]] -> 40000 | N14: 192000 | O14: =Tabla3[[#This Row],[VLR. TOTAL FACT.]]-Tabla3[[#This Row],[VLR. TRANSPORTE]] -> 152000 | P14: 0 | Q14: efectivo
A15: 58924 | B15: 45980 | C15: sai | D15: Martha Rosero | E15: Tortolas | F15: 4 | G15: =_xlfn.XLOOKUP(Tabla3[[#This Row],[ID]],Tabla2[ID],Tabla2[Corregimiento],"NA") -> El Carmen | H15: =_xlfn.XLOOKUP(Tabla3[[#This Row],[LUGAR ENVÍO]],Tabla9[[Nombre ]],Tabla9[Distancia],"NA") -> 5.757 | I15: =Tabla3[[#This Row],[Valor Tran]]/(Tabla3[[#This Row],[DISTANCIA (km)]]*2) -> 4342.5395 | K15: 1 | L15: 50000 | M15: =Tabla3[[#This Row],[VLR. TRANSPORTE]]/Tabla3[[#This Row],[Numero de Transportes]] -> 50000 | N15: 242000 | O15: =Tabla3[[#This Row],[VLR. TOTAL FACT.]]-Tabla3[[#This Row],[VLR. TRANSPORTE]] -> 192000 | P15: 0 | Q15: efectivo
A16: 48280 | B16: 45982 | C16: sai | D16: julio daza | E16: Tortolas | F16: 4 | G16: =_xlfn.XLOOKUP(Tabla3[[#This Row],[ID]],Tabla2[ID],Tabla2[Corregimiento],"NA") -> El Carmen | H16: =_xlfn.XLOOKUP(Tabla3[[#This Row],[LUGAR ENVÍO]],Tabla9[[Nombre ]],Tabla9[Distancia],"NA") -> 5.757 | I16: =Tabla3[[#This Row],[Valor Tran]]/(Tabla3[[#This Row],[DISTANCIA (km)]]*2) -> 2605.5237 | K16: 1 | L16: 30000 | M16: =Tabla3[[#This Row],[VLR. TRANSPORTE]]/Tabla3[[#This Row],[Numero de Transportes]] -> 30000 | N16: 575700 | O16: =Tabla3[[#This Row],[VLR. TOTAL FACT.]]-Tabla3[[#This Row],[VLR. TRANSPORTE]] -> 545700 | P16: 0 | Q16: transferencia
A17: 58571 | B17: 45989 | C17: sai | D17: Julio Daza | E17: Tortolas | F17: 4 | G17: =_xlfn.XLOOKUP(Tabla3[[#This Row],[ID]],Tabla2[ID],Tabla2[Corregimiento],"NA") -> El Carmen | H17: =_xlfn.XLOOKUP(Tabla3[[#This Row],[LUGAR ENVÍO]],Tabla9[[Nombre ]],Tabla9[Distancia],"NA") -> 5.757 | I17: =Tabla3[[#This Row],[Valor Tran]]/(Tabla3[[#This Row],[DISTANCIA (km)]]*2) -> 5211.0474 | K17: 1 | L17: 60000 | M17: =Tabla3[[#This Row],[VLR. TRANSPORTE]]/Tabla3[[#This Row],[Numero de Transportes]] -> 60000 | N17: 1045000 | O17: =Tabla3[[#This Row],[VLR. TOTAL FACT.]]-Tabla3[[#This Row],[VLR. TRANSPORTE]] -> 985000 | P17: 1 | Q17: Transferencia
A18: 51291 | B18: 2025-11-07 | C18: manual | D18: Ferney Bernal | E18: Tortolas | F18: 4 | G18: =_xlfn.XLOOKUP(Tabla3[[#This Row],[ID]],Tabla2[ID],Tabla2[Corregimiento],"NA") -> El Carmen | H18: =_xlfn.XLOOKUP(Tabla3[[#This Row],[LUGAR ENVÍO]],Tabla9[[Nombre ]],Tabla9[Distancia],"NA") -> 5.757 | I18: =Tabla3[[#This Row],[Valor Tran]]/(Tabla3[[#This Row],[DISTANCIA (km)]]*2) -> 6948.0632 | K18: 1 | L18: 80000 | M18: 80000 | N18: 1245200 | O18: =Tabla3[[#This Row],[VLR. TOTAL FACT.]]-Tabla3[[#This Row],[VLR. TRANSPORTE]] -> 1165200 | P18: 1 | Q18: tarjeta
A19: 59047 | B19: 45989 | C19: sai | D19: Martha Rosero | E19: Tortolas | F19: 4 | G19: =_xlfn.XLOOKUP(Tabla3[[#This Row],[ID]],Tabla2[ID],Tabla2[Corregimiento],"NA") -> El Carmen | H19: =_xlfn.XLOOKUP(Tabla3[[#This Row],[LUGAR ENVÍO]],Tabla9[[Nombre ]],Tabla9[Distancia],"NA") -> 5.757 | I19: =Tabla3[[#This Row],[Valor Tran]]/(Tabla3[[#This Row],[DISTANCIA (km)]]*2) -> 13896.126 | K19: 1 | L19: 160000 | M19: =Tabla3[[#This Row],[VLR. TRANSPORTE]]/Tabla3[[#This Row],[Numero de Transportes]] -> 160000 | N19: 1704900 | O19: =Tabla3[[#This Row],[VLR. TOTAL FACT.]]-Tabla3[[#This Row],[VLR. TRANSPORTE]] -> 1544900 | P19: 1 | Q19: efectivo
A20: 46906 | B20: 45966 | C20: sai | D20: martha rosero | E20: Tortolas | F20: 4 | G20: =_xlfn.XLOOKUP(Tabla3[[#This Row],[ID]],Tabla2[ID],Tabla2[Corregimiento],"NA") -> El Carmen | H20: =_xlfn.XLOOKUP(Tabla3[[#This Row],[LUGAR ENVÍO]],Tabla9[[Nombre ]],Tabla9[Distancia],"NA") -> 5.757 | I20: =Tabla3[[#This Row],[Valor Tran]]/(Tabla3[[#This Row],[DISTANCIA (km)]]*2) -> 6948.0632 | K20: 2 | L20: 160000 | M20: =Tabla3[[#This Row],[VLR. TRANSPORTE]]/Tabla3[[#This Row],[Numero de Transportes]] -> 80000 | N20: 1915000 | O20: =Tabla3[[#This Row],[VLR. TOTAL FACT.]]-Tabla3[[#This Row],[VLR. TRANSPORTE]] -> 1755000 | P20: 1 | Q20: transferencia
A21: 46903 | B21: 45967 | C21: sai | D21: eduardo olaus | E21: Tocota | F21: 22 | G21: =_xlfn.XLOOKUP(Tabla3[[#This Row],[ID]],Tabla2[ID],Tabla2[Corregimiento],"NA") -> San Bernardo | H21: =_xlfn.XLOOKUP(Tabla3[[#This Row],[LUGAR ENVÍO]],Tabla9[[Nombre ]],Tabla9[Distancia],"NA") -> 9.438 | I21: =Tabla3[[#This Row],[Valor Tran]]/(Tabla3[[#This Row],[DISTANCIA (km)]]*2) -> 2648.8663 | K21: 1 | L21: 50000 | M21: =Tabla3[[#This Row],[VLR. TRANSPORTE]]/Tabla3[[#This Row],[Numero de Transportes]] -> 50000 | N21: 428000 | O21: =Tabla3[[#This Row],[VLR. TOTAL FACT.]]-Tabla3[[#This Row],[VLR. TRANSPORTE]] -> 378000 | P21: 0 | Q21: transferencia
A22: 30503 | B22: 45973 | C22: sai | D22: Guerardo Hernandez | E22: Tocota | F22: 22 | G22: =_xlfn.XLOOKUP(Tabla3[[#This Row],[ID]],Tabla2[ID],Tabla2[Corregimiento],"NA") -> San Bernardo | H22: =_xlfn.XLOOKUP(Tabla3[[#This Row],[LUGAR ENVÍO]],Tabla9[[Nombre ]],Tabla9[Distancia],"NA") -> 9.438 | I22: =Tabla3[[#This Row],[Valor Tran]]/(Tabla3[[#This Row],[DISTANCIA (km)]]*2) -> 3178.6395 | K22: 1 | L22: 60000 | M22: =Tabla3[[#This Row],[VLR. TRANSPORTE]]/Tabla3[[#This Row],[Numero de Transportes]] -> 60000 | N22: 750000 | O22: =Tabla3[[#This Row],[VLR. TOTAL FACT.]]-Tabla3[[#This Row],[VLR. TRANSPORTE]] -> 690000 | P22: 0 | Q22: Transferencia
A23: 58870 | B23: 45985 | C23: sai | D23: diego zuluaga | E23: Tocota | F23: 22 | G23: =_xlfn.XLOOKUP(Tabla3[[#This Row],[ID]],Tabla2[ID],Tabla2[Corregimiento],"NA") -> San Bernardo | H23: =_xlfn.XLOOKUP(Tabla3[[#This Row],[LUGAR ENVÍO]],Tabla9[[Nombre ]],Tabla9[Distancia],"NA") -> 9.438 | I23: =Tabla3[[#This Row],[Valor Tran]]/(Tabla3[[#This Row],[DISTANCIA (km)]]*2) -> 1589.3198 | K23: 2 | L23: 60000 | M23: =Tabla3[[#This Row],[VLR. TRANSPORTE]]/Tabla3[[#This Row],[Numero de Transportes]] -> 30000 | N23: 829000 | O23: =Tabla3[[#This Row],[VLR. TOTAL FACT.]]-Tabla3[[#This Row],[VLR. TRANSPORTE]] -> 769000 | P23: 1 | Q23: tarjeta
A24: 57102 | B24: 45989 | C24: sai | D24: Jose Murillo | E24: Tocota | F24: 22 | G24: =_xlfn.XLOOKUP(Tabla3[[#This Row],[ID]],Tabla2[ID],Tabla2[Corregimiento],"NA") -> San Bernardo | H24: =_xlfn.XLOOKUP(Tabla3[[#This Row],[LUGAR ENVÍO]],Tabla9[[Nombre ]],Tabla9[Distancia],"NA") -> 9.438 | I24: =Tabla3[[#This Row],[Valor Tran]]/(Tabla3[[#This Row],[DISTANCIA (km)]]*2) -> 3178.6395 | K24: 1 | L24: 60000 | M24: =Tabla3[[#This Row],[VLR. TRANSPORTE]]/Tabla3[[#This Row],[Numero de Transportes]] -> 60000 | N24: 1186000 | O24: =Tabla3[[#This Row],[VLR. TOTAL FACT.]]-Tabla3[[#This Row],[VLR. TRANSPORTE]] -> 1126000 | P24: 0 | Q24: efectivo
A25: 30560 | B25: 45979 | C25: sai | D25: NA | E25: Tocota | F25: 22 | G25: =_xlfn.XLOOKUP(Tabla3[[#This Row],[ID]],Tabla2[ID],Tabla2[Corregimiento],"NA") -> San Bernardo | H25: =_xlfn.XLOOKUP(Tabla3[[#This Row],[LUGAR ENVÍO]],Tabla9[[Nombre ]],Tabla9[Distancia],"NA") -> 9.438 | I25: =Tabla3[[#This Row],[Valor Tran]]/(Tabla3[[#This Row],[DISTANCIA (km)]]*2) -> 3178.6395 | K25: 1 | L25: 60000 | M25: =Tabla3[[#This Row],[VLR. TRANSPORTE]]/Tabla3[[#This Row],[Numero de Transportes]] -> 60000 | N25: 1479500 | O25: =Tabla3[[#This Row],[VLR. TOTAL FACT.]]-Tabla3[[#This Row],[VLR. TRANSPORTE]] -> 1419500 | P25: 0 | Q25: Tarjeta
A26: 58552 | B26: 45977 | C26: manual | D26: jose correa | E26: Tierras blancas | F26: 2 | G26: =_xlfn.XLOOKUP(Tabla3[[#This Row],[ID]],Tabla2[ID],Tabla2[Corregimiento],"NA") -> Borrero Ayerbe | H26: =_xlfn.XLOOKUP(Tabla3[[#This Row],[LUGAR ENVÍO]],Tabla9[[Nombre ]],Tabla9[Distancia],"NA") -> 0.449 | I26: =Tabla3[[#This Row],[Valor Tran]]/(Tabla3[[#This Row],[DISTANCIA (km)]]*2) -> 27839.644 | K26: 1 | L26: 25000 | M26: =Tabla3[[#This Row],[VLR. TRANSPORTE]]/Tabla3[[#This Row],[Numero de Transportes]] -> 25000 | N26: 590000 | O26: =Tabla3[[#This Row],[VLR. TOTAL FACT.]]-Tabla3[[#This Row],[VLR. TRANSPORTE]] -> 565000 | P26: 1 | Q26: efectivo
A27: 58977 | B27: 2025-11-21 | C27: sai | D27: Maria Del Carmen | E27: Tierras blancas | F27: 2 | G27: =_xlfn.XLOOKUP(Tabla3[[#This Row],[ID]],Tabla2[ID],Tabla2[Corregimiento],"NA") -> Borrero Ayerbe | H27: =_xlfn.XLOOKUP(Tabla3[[#This Row],[LUGAR ENVÍO]],Tabla9[[Nombre ]],Tabla9[Distancia],"NA") -> 0.449 | I27: =Tabla3[[#This Row],[Valor Tran]]/(Tabla3[[#This Row],[DISTANCIA (km)]]*2) -> 33407.572 | K27: 1 | L27: 30000 | M27: 30000 | N27: 627100 | O27: =Tabla3[[#This Row],[VLR. TOTAL FACT.]]-Tabla3[[#This Row],[VLR. TRANSPORTE]] -> 597100 | P27: 1 | Q27: efectivo
A28: 58706 | B28: 45984 | C28: sai | D28: sergio bautista | E28: Tierras blancas | F28: 2 | G28: =_xlfn.XLOOKUP(Tabla3[[#This Row],[ID]],Tabla2[ID],Tabla2[Corregimiento],"NA") -> Borrero Ayerbe | H28: =_xlfn.XLOOKUP(Tabla3[[#This Row],[LUGAR ENVÍO]],Tabla9[[Nombre ]],Tabla9[Distancia],"NA") -> 0.449 | I28: =Tabla3[[#This Row],[Valor Tran]]/(Tabla3[[#This Row],[DISTANCIA (km)]]*2) -> 55679.287 | K28: 3 | L28: 150000 | M28: =Tabla3[[#This Row],[VLR. TRANSPORTE]]/Tabla3[[#This Row],[Numero de Transportes]] -> 50000 | N28: 1342000 | O28: =Tabla3[[#This Row],[VLR. TOTAL FACT.]]-Tabla3[[#This Row],[VLR. TRANSPORTE]] -> 1192000 | P28: 1 | Q28: tarjeta
A29: 46572 | B29: 2025-11-17 | C29: sai | D29: Sandra Palomino | E29: San miguel | F29: 2 | G29: =_xlfn.XLOOKUP(Tabla3[[#This Row],[ID]],Tabla2[ID],Tabla2[Corregimiento],"NA") -> Borrero Ayerbe | H29: =_xlfn.XLOOKUP(Tabla3[[#This Row],[LUGAR ENVÍO]],Tabla9[[Nombre ]],Tabla9[Distancia],"NA") -> 2.269 | I29: =Tabla3[[#This Row],[Valor Tran]]/(Tabla3[[#This Row],[DISTANCIA (km)]]*2) -> 15425.297 | K29: 1 | L29: 70000 | M29: 70000 | N29: 441600 | O29: =Tabla3[[#This Row],[VLR. TOTAL FACT.]]-Tabla3[[#This Row],[VLR. TRANSPORTE]] -> 371600 | P29: 1 | Q29: efectivo
A30: 51992 | B30: 2025-11-17 | C30: sai | D30: Mario Duran | E30: San miguel | F30: 2 | G30: =_xlfn.XLOOKUP(Tabla3[[#This Row],[ID]],Tabla2[ID],Tabla2[Corregimiento],"NA") -> Borrero Ayerbe | H30: =_xlfn.XLOOKUP(Tabla3[[#This Row],[LUGAR ENVÍO]],Tabla9[[Nombre ]],Tabla9[Distancia],"NA") -> 2.269 | I30: =Tabla3[[#This Row],[Valor Tran]]/(Tabla3[[#This Row],[DISTANCIA (km)]]*2) -> 17628.911 | K30: 1 | L30: 80000 | M30: 80000 | N30: 491200 | O30: =Tabla3[[#This Row],[VLR. TOTAL FACT.]]-Tabla3[[#This Row],[VLR. TRANSPORTE]] -> 411200 | P30: 1 | Q30: transferencia
A31: 0 | B31: 45983 | C31: sai | D31: mireya lopez | E31: San Miguel | F31: 2 | G31: =_xlfn.XLOOKUP(Tabla3[[#This Row],[ID]],Tabla2[ID],Tabla2[Corregimiento],"NA") -> Borrero Ayerbe | H31: =_xlfn.XLOOKUP(Tabla3[[#This Row],[LUGAR ENVÍO]],Tabla9[[Nombre ]],Tabla9[Distancia],"NA") -> 2.269 | I31: =Tabla3[[#This Row],[Valor Tran]]/(Tabla3[[#This Row],[DISTANCIA (km)]]*2) -> 15425.297 | K31: 1 | L31: 70000 | M31: =Tabla3[[#This Row],[VLR. TRANSPORTE]]/Tabla3[[#This Row],[Numero de Transportes]] -> 70000 | N31: 541100 | O31: =Tabla3[[#This Row],[VLR. TOTAL FACT.]]-Tabla3[[#This Row],[VLR. TRANSPORTE]] -> 471100 | P31: 1 | Q31: NA
A32: 57498 | B32: 2025-11-29 | C32: sai | D32: Sandra Palomino | E32: San miguel | F32: 2 | G32: =_xlfn.XLOOKUP(Tabla3[[#This Row],[ID]],Tabla2[ID],Tabla2[Corregimiento],"NA") -> Borrero Ayerbe | H32: =_xlfn.XLOOKUP(Tabla3[[#This Row],[LUGAR ENVÍO]],Tabla9[[Nombre ]],Tabla9[Distancia],"NA") -> 2.269 | I32: =Tabla3[[#This Row],[Valor Tran]]/(Tabla3[[#This Row],[DISTANCIA (km)]]*2) -> 15425.297 | K32: 1 | L32: 70000 | M32: 70000 | N32: 558600 | O32: =Tabla3[[#This Row],[VLR. TOTAL FACT.]]-Tabla3[[#This Row],[VLR. TRANSPORTE]] -> 488600 | P32: 1 | Q32: efectivo
A33: 47307 | B33: 2025-11-25 | C33: sai | D33: Luis Fernando | E33: San miguel | F33: 2 | G33: =_xlfn.XLOOKUP(Tabla3[[#This Row],[ID]],Tabla2[ID],Tabla2[Corregimiento],"NA") -> Borrero Ayerbe | H33: =_xlfn.XLOOKUP(Tabla3[[#This Row],[LUGAR ENVÍO]],Tabla9[[Nombre ]],Tabla9[Distancia],"NA") -> 2.269 | I33: =Tabla3[[#This Row],[Valor Tran]]/(Tabla3[[#This Row],[DISTANCIA (km)]]*2) -> 15425.297 | K33: 1 | L33: 70000 | M33: 70000 | N33: 626400 | O33: =Tabla3[[#This Row],[VLR. TOTAL FACT.]]-Tabla3[[#This Row],[VLR. TRANSPORTE]] -> 556400 | P33: 1 | Q33: efectivo
A34: 58146 | B34: 2025-11-10 | C34: sai | D34: Monica Pastrana | E34: San miguel | F34: 2 | G34: =_xlfn.XLOOKUP(Tabla3[[#This Row],[ID]],Tabla2[ID],Tabla2[Corregimiento],"NA") -> Borrero Ayerbe | H34: =_xlfn.XLOOKUP(Tabla3[[#This Row],[LUGAR ENVÍO]],Tabla9[[Nombre ]],Tabla9[Distancia],"NA") -> 2.269 | I34: =Tabla3[[#This Row],[Valor Tran]]/(Tabla3[[#This Row],[DISTANCIA (km)]]*2) -> 15425.297 | K34: 1 | L34: 70000 | M34: 70000 | N34: 648300 | O34: =Tabla3[[#This Row],[VLR. TOTAL FACT.]]-Tabla3[[#This Row],[VLR. TRANSPORTE]] -> 578300 | P34: 1 | Q34: efectivo
A35: 58837 | B35: 45995 | C35: sai | D35: jhon cruz | E35: San Miguel | F35: 2 | G35: =_xlfn.XLOOKUP(Tabla3[[#This Row],[ID]],Tabla2[ID],Tabla2[Corregimiento],"NA") -> Borrero Ayerbe | H35: =_xlfn.XLOOKUP(Tabla3[[#This Row],[LUGAR ENVÍO]],Tabla9[[Nombre ]],Tabla9[Distancia],"NA") -> 2.269 | I35: =Tabla3[[#This Row],[Valor Tran]]/(Tabla3[[#This Row],[DISTANCIA (km)]]*2) -> 6610.8418 | K35: 1 | L35: 30000 | M35: =Tabla3[[#This Row],[VLR. TRANSPORTE]]/Tabla3[[#This Row],[Numero de Transportes]] -> 30000 | N35: 2391000 | O35: =Tabla3[[#This Row],[VLR. TOTAL FACT.]]-Tabla3[[#This Row],[VLR. TRANSPORTE]] -> 2361000 | P35: 1 | Q35: transferencia
A36: 47219 | B36: 45971 | C36: sai | D36: juan barado | E36: San Jose del Salado | F36: 12 | G36: =_xlfn.XLOOKUP(Tabla3[[#This Row],[ID]],Tabla2[ID],Tabla2[Corregimiento],"NA") -> El Salado | H36: =_xlfn.XLOOKUP(Tabla3[[#This Row],[LUGAR ENVÍO]],Tabla9[[Nombre ]],Tabla9[Distancia],"NA") -> 13.07 | I36: =Tabla3[[#This Row],[Valor Tran]]/(Tabla3[[#This Row],[DISTANCIA (km)]]*2) -> 1530.2219 | K36: 1 | L36: 40000 | M36: =Tabla3[[#This Row],[VLR. TRANSPORTE]]/Tabla3[[#This Row],[Numero de Transportes]] -> 40000 | N36: 401900 | O36: =Tabla3[[#This Row],[VLR. TOTAL FACT.]]-Tabla3[[#This Row],[VLR. TRANSPORTE]] -> 361900 | P36: 1 | Q36: transferenica
A37: 48298 | B37: 45982 | C37: sai | D37: monica pastrana | E37: San Jose del Salado | F37: 12 | G37: =_xlfn.XLOOKUP(Tabla3[[#This Row],[ID]],Tabla2[ID],Tabla2[Corregimiento],"NA") -> El Salado | H37: =_xlfn.XLOOKUP(Tabla3[[#This Row],[LUGAR ENVÍO]],Tabla9[[Nombre ]],Tabla9[Distancia],"NA") -> 13.07 | I37: =Tabla3[[#This Row],[Valor Tran]]/(Tabla3[[#This Row],[DISTANCIA (km)]]*2) -> 2677.8883 | K37: 1 | L37: 70000 | M37: =Tabla3[[#This Row],[VLR. TRANSPORTE]]/Tabla3[[#This Row],[Numero de Transportes]] -> 70000 | N37: 542500 | O37: =Tabla3[[#This Row],[VLR. TOTAL FACT.]]-Tabla3[[#This Row],[VLR. TRANSPORTE]] -> 472500 | P37: 1 | Q37: efectivo
A38: 50256 | B38: 2025-11-22 | C38: sai | D38: Antonio Jimenez | E38: San Jose del Salado | F38: 12 | G38: =_xlfn.XLOOKUP(Tabla3[[#This Row],[ID]],Tabla2[ID],Tabla2[Corregimiento],"NA") -> El Salado | H38: =_xlfn.XLOOKUP(Tabla3[[#This Row],[LUGAR ENVÍO]],Tabla9[[Nombre ]],Tabla9[Distancia],"NA") -> 13.07 | I38: =Tabla3[[#This Row],[Valor Tran]]/(Tabla3[[#This Row],[DISTANCIA (km)]]*2) -> 1530.2219 | K38: 2 | L38: 80000 | M38: 40000 | N38: 633400 | O38: =Tabla3[[#This Row],[VLR. TOTAL FACT.]]-Tabla3[[#This Row],[VLR. TRANSPORTE]] -> 553400 | P38: 1 | Q38: transferencia
A39: 46985 | B39: 45968 | C39: sai | D39: carlos gawes | E39: San Jose del Salado | F39: 12 | G39: =_xlfn.XLOOKUP(Tabla3[[#This Row],[ID]],Tabla2[ID],Tabla2[Corregimiento],"NA") -> El Salado | H39: =_xlfn.XLOOKUP(Tabla3[[#This Row],[LUGAR ENVÍO]],Tabla9[[Nombre ]],Tabla9[Distancia],"NA") -> 13.07 | I39: =Tabla3[[#This Row],[Valor Tran]]/(Tabla3[[#This Row],[DISTANCIA (km)]]*2) -> 1912.7774 | K39: 1 | L39: 50000 | M39: =Tabla3[[#This Row],[VLR. TRANSPORTE]]/Tabla3[[#This Row],[Numero de Transportes]] -> 50000 | N39: 961900 | O39: =Tabla3[[#This Row],[VLR. TOTAL FACT.]]-Tabla3[[#This Row],[VLR. TRANSPORTE]] -> 911900 | P39: 0 | Q39: transferencia
A40: 46966 | B40: 2025-11-15 | C40: sai | D40: Gustavo Chaux | E40: San Jose del Salado | F40: 12 | G40: =_xlfn.XLOOKUP(Tabla3[[#This Row],[ID]],Tabla2[ID],Tabla2[Corregimiento],"NA") -> El Salado | H40: =_xlfn.XLOOKUP(Tabla3[[#This Row],[LUGAR ENVÍO]],Tabla9[[Nombre ]],Tabla9[Distancia],"NA") -> 13.07 | I40: =Tabla3[[#This Row],[Valor Tran]]/(Tabla3[[#This Row],[DISTANCIA (km)]]*2) -> 2677.8883 | K40: 1 | L40: 70000 | M40: 70000 | N40: 1105700 | O40: =Tabla3[[#This Row],[VLR. TOTAL FACT.]]-Tabla3[[#This Row],[VLR. TRANSPORTE]] -> 1035700 | P40: 1 | Q40: efectivo
...

Sheet Hoja1
A1: Nombre | B1: Numero de envios | C1: Distancia
A2: El Coscorron | B2: =COUNTIF(Tabla3[LUGAR ENVÍO],Tabla9[[#This Row],[Nombre ]]) -> 11 | C2: =Distancias!EA61 -> 2.65
A3: Altos del Carmen | B3: =COUNTIF(Tabla3[LUGAR ENVÍO],Tabla9[[#This Row],[Nombre ]]) -> 9 | C3: =Distancias!DO118 -> 5.464 | F3: Ubicación | G3: Envios | H3: Total valor del transporte | I3: Valor promedio de transporte | J3: Total de venta | K3: G/P promedio Margen
A4: Pirineos | B4: =COUNTIF(Tabla3[LUGAR ENVÍO],Tabla9[[#This Row],[Nombre ]]) -> 9 | C4: =Distancias!DC47 -> 2.66665 | F4: El Diviso | G4: =COUNTIF(Tabla3[LUGAR ENVÍO],Tabla11[[#This Row],[Ubicación]]) -> 6 | H4: =SUMIF(Tabla3[LUGAR ENVÍO],Tabla11[[#This Row],[Ubicación]],Tabla3[VLR. TRANSPORTE]) -> 360000 | I4: =AVERAGEIF(Tabla3[LUGAR ENVÍO],Tabla11[[#This Row],[Ubicación]],Tabla3[VLR. TRANSPORTE]) -> 60000 | J4: =SUMIF(Tabla3[LUGAR ENVÍO],Tabla11[[#This Row],[Ubicación]],Tabla3[VLR. TOTAL FACT.]) -> 16869200 | K4: =AVERAGEIF(Tabla8[Lugar],Tabla11[[#This Row],[Ubicación]],Tabla8[Perdida o ganancia de margen]) -> -0.1100685
A5: KM 34 | B5: =COUNTIF(Tabla3[LUGAR ENVÍO],Tabla9[[#This Row],[Nombre ]]) -> 8 | C5: =Distancias!DG63 -> 4.316 | F5: Tocota | G5: =COUNTIF(Tabla3[LUGAR ENVÍO],Tabla11[[#This Row],[Ubicación]]) -> 5 | H5: =SUMIF(Tabla3[LUGAR ENVÍO],Tabla11[[#This Row],[Ubicación]],Tabla3[VLR. TRANSPORTE]) -> 290000 | I5: =AVERAGEIF(Tabla3[LUGAR ENVÍO],Tabla11[[#This Row],[Ubicación]],Tabla3[VLR. TRANSPORTE]) -> 58000 | J5: =SUMIF(Tabla3[LUGAR ENVÍO],Tabla11[[#This Row],[Ubicación]],Tabla3[VLR. TOTAL FACT.]) -> 4672500 | K5: =AVERAGEIF(Tabla8[Lugar],Tabla11[[#This Row],[Ubicación]],Tabla8[Perdida o ganancia de margen]) -> -0.15768468
